Workbook

Sheet Резюме для инвестора
A1: ATARIA — инвестиционное предложение (резюме)
A2: Займ на закупку кухонных комбайнов AT-SM23 и ортопедических подушек для продажи на Kaspi.kz и в Instagram. Все цифры — из модели, меняются вместе с «Допущениями».
A4: ПАРАМЕТРЫ СДЕЛКИ
A5: Сумма займа всего, ₸ | B5: =Допущения!$B$6+Допущения!$B$7+Допущения!$B$9+Допущения!$B$10 -> 9000000
A6: остаток 70% за готовую партию комбайнов (200 шт.), ₸ | B6: =Допущения!$B$6 -> 6000000
A7: карго (доставка партии комбайнов), ₸ | B7: =Допущения!$B$7 -> 1500000
A8: ортопедические подушки, ₸ | B8: =Допущения!$B$9 -> 1500000
A9: Вклад владельца (депозит 30% уже оплачен), ₸ | B9: =Допущения!$B$8 -> 2500000
A10: Ставка, % в месяц | B10: =Допущения!$B$12 -> 0.04
A11: Проценты в месяц, ₸ | B11: ='График платежей'!D5 -> 360000
A12: Срок, мес. | B12: =Допущения!$B$13 -> 12
A13: Возврат тела займа | B13: одним платежом в последний месяц
A14: Итого инвестор получает, ₸ | B14: ='График платежей'!F17 -> 13320000
A15: из них доход инвестора, ₸ | B15: ='График платежей'!D17 -> 4320000
A17: ИСТОРИЯ ПРОДАЖ (Kaspi, фев–окт 2026)
A18: Реальная выручка бренда Ataria, ₸ | B18: ='Анализ продаж Kaspi'!B9 -> 46561590
A19: Лучший месяц (август 2026), ₸ | B19: 13086530
A20: Продано комбайнов AT-SM23 за 3 мес. с запуска, шт. | B20: 170
A21: Продано подушек, шт. | B21: 1306
A22: Фактическая прибыль до пост. расходов (март–окт.), ₸ | B22: ='Факт прибыли 2026'!K14 -> 7385394.1
A24: ПРОГНОЗ ПРОЕКТА (12 мес., выбранный сценарий)
A25: Сценарий | B25: =INDEX({"Пессимистичный","Базовый","Оптимистичный"},Допущения!$B$16) -> Базовый
A26: Выручка проекта, ₸ | B26: ='План и ДДС'!P42 -> 92619592
A27: Продано комбайнов, шт. | B27: ='План и ДДС'!P13 -> 583
A28: Продано подушек, шт. | B28: ='План и ДДС'!P24+'План и ДДС'!P35 -> 2130
A29: Чистая прибыль после выплаты процентов, ₸ | B29: ='План и ДДС'!P57 -> 6507391.6
A30: Деньги проекта после полного возврата займа, ₸ | B30: ='План и ДДС'!$C$62 -> 8112391.6
A31: + товар на складе по себестоимости, ₸ | B31: ='План и ДДС'!$C$63 -> 895000
A32: Минимальный остаток денег за период, ₸ | B32: ='План и ДДС'!$C$64 -> 1095000
A33: Минимальное покрытие процентов прибылью, x | B33: ='План и ДДС'!$C$65 -> 1.6071415
A35: ЮНИТ-ЭКОНОМИКА
A36: Комбайн: прибыль с 1 шт. после всех переменных расходов, ₸ | B36: ='Юнит-экономика'!B15 -> 15413.525
A37: Комбайн: наценка на себестоимость | B37: ='Юнит-экономика'!B13 -> 1.23028
A38: Подушка 35×60: прибыль с 1 шт., ₸ | B38: ='Юнит-экономика'!C15 -> 2215.8281
A39: Подушка 40×60: прибыль с 1 шт., ₸ | B39: ='Юнит-экономика'!D15 -> 2893.3796
A40: Подушки: наценка на себестоимость | B40: =AVERAGE('Юнит-экономика'!C13:D13) -> 1.8758

Sheet Допущения
A1: ATARIA — допущения инвестиционной модели
A2: Синий шрифт = ввод (можно менять). Жёлтая заливка = цифра-оценка, которую нужно подтвердить. Источник каждой цифры — в столбце D.
A5: 1. Займ инвестора
A6: Остаток 70% за готовую партию комбайнов (200 шт.), ₸ | B6: 6000000 | D6: Со слов владельца: партия 200 шт. готова, депозит 30% (~2,5 млн) владелец уже оплатил сам
A7: Оплата карго (доставка партии комбайнов), ₸ | B7: 1500000 | D7: Со слов владельца: 1,5–2 млн через ~2 недели после оплаты остатка
A8: Вклад владельца — уже оплаченный депозит 30%, ₸ | B8: 2500000 | D8: Со слов владельца: 2–2,5 млн (собственные деньги, не из займа)
A9: Сумма займа на подушки, ₸ | B9: 1500000 | D9: Со слов владельца: 1–2 млн, в базе взята середина
A10: Резервный транш 2 (при необходимости), ₸ | B10: 0 | D10: По расчёту модели не нужен: дозакупки оплачиваются из выручки. Можно задать для стресс-сценария
A11: Месяц получения транша 2 | B11: 3 | D11: Месяц, когда нужно оплатить остаток 70% за 2-ю партию
A12: Ставка, % в месяц | B12: 0.04 | D12: Со слов владельца: 4% ежемесячно, тело — в конце срока
A13: Срок займа, мес. | B13: 12 | D13: Со слов владельца: от 1 года (модель рассчитана на 12 мес.)
A15: 2. Сценарий
A16: Выбранный сценарий (1 = пессимист., 2 = базовый, 3 = оптимист.) | B16: 2 | D16: Переключатель — меняет объём продаж во всей модели
A17: Множитель объёма продаж — пессимистичный | B17: 0.7 | D17: Пессимист: −30% к базе (как спад сентября vs августа); оптимист: +30% (уровень августа)
A18: — базовый | B18: 1
A19: — оптимистичный | B19: 1.3
A20: Применяемый множитель | B20: =INDEX(B17:B19,$B$16) -> 1
A22: 3. Товары (себестоимость с доставкой до РК, цена продажи, спрос)
A23: Показатель | B23: Кухонный комбайн AT-SM23 | C23: Подушка 35×60 | D23: Подушка 40×60 | E23: Источник
A24: Себестоимость единицы (с доставкой), ₸ | B24: 50000 | C24: 4000 | D24: 5000 | E24: Со слов владельца: комбайн 50 000 (с доставкой), подушка 35×60 — 4 000, 40×60 — 5 000, 40×61 — 5 300
A25: Цена продажи на Kaspi (средняя фактическая за всё время), ₸ | B25: 111514 | C25: 11344 | D25: 14578 | E25: Kaspi: средневзвешенная цена всех реальных продаж (комбайн 99 990 → 129 990, подушки 9 990 → 17 990). Текущие цены выше — это запас прочности
A26: Базовый спрос, шт./мес. | B26: 50 | C26: 100 | D26: 100 | E26: Kaspi: комбайн авг 85 / сен 55 / окт ~34 за мес. при цене 125 тыс.; подушки 35×60 ≈ 100, 40×60 (вкл. 40×61) ≈ 95 в сентябре
A27: Комиссия Kaspi, % от цены | B27: 0.109 | C27: 0.113 | D27: 0.113 | E27: Со слов владельца: факт Kaspi — 10,9% техника, 11,3% подушки
A28: Маркетинг (реклама Kaspi + бонусы + отзывы), % от выручки | B28: ='Анализ маркетинга'!H5 -> 0.22208905 | C28: ='Анализ маркетинга'!H6 -> 0.20608426 | D28: ='Анализ маркетинга'!H6 -> 0.20608426 | E28: Факт янв–окт 2026 по отчётам Kaspi (лист «Анализ маркетинга»): комбайн 22%, подушки 21% от реальной выручки
A29: Доставка Kaspi за счёт продавца, ₸/шт. | B29: 1931 | C29: 998 | D29: 1377 | E29: Kaspi: «Стоимость доставки для продавца», среднее по фактическим выдачам
A30: Возвраты, % от выручки | B30: 0.025 | C30: 0.005 | D30: 0.005 | E30: Kaspi: доля возвратов по реальным заказам (комбайн 2,5%, подушки 0,1–0,4%)
A31: Производство: оплата остатка 70% через, мес. | B31: 2 | C31: 1 | D31: 1 | E31: Со слов владельца: комбайн 45–60 дн., подушки 15–20 дн.
A32: Поступление на склад после заказа, мес. | B32: 3 | C32: 2 | D32: 2 | E32: Производство + доставка 20–25 дн., с запасом
A33: Минимальная партия (MOQ), шт. | B33: 200 | C33: 50 | D33: 50 | E33: Со слов владельца
A35: 4. Общие расходы
A36: Предоплата поставщику при заказе, % | B36: 0.3 | D36: Со слов владельца: депозит 30%, остаток — перед отгрузкой
A37: Налог (упрощённая декларация), % от выручки | B37: 0.04 | D37: Со слов владельца: ИП на упрощённой декларации, налог 4% от выручки
A38: Постоянные расходы (персонал, склад, сервисы), ₸/мес. | B38: 300000 | D38: Со слов владельца: до 300 000 ₸ в месяц
A39: Готовая партия комбайнов (поступает в мес. 1), шт. | B39: 200 | D39: Со слов владельца: партия = MOQ 200 шт. по 50 000 ₸ (депозит + остаток + карго ≈ 10 млн)

Sheet План и ДДС
A1: ATARIA — план продаж и движение денег по проекту (12 мес.)
A2: Месяц 0 — получение займа и оплата закупок. Продажи — только товар, закупленный в рамках проекта (текущие остатки не учтены). Жёлтые строки «Заказ у поставщика» — график закупок, можно менять.
A4: Показатель | B4: Ед. | C4: Мес. 0 окт 26 | D4: Мес. 1 ноя 26 | E4: Мес. 2 дек 26 | F4: Мес. 3 янв 27 | G4: Мес. 4 фев 27 | H4: Мес. 5 мар 27 | I4: Мес. 6 апр 27 | J4: Мес. 7 май 27 | K4: Мес. 8 июн 27 | L4: Мес. 9 июл 27 | M4: Мес. 10 авг 27 | N4: Мес. 11 сен 27 | O4: Мес. 12 окт 27 | P4: Итого
A5: Сезонность
A6: Коэффициент сезонности спроса | B6: x | D6: 1.15 | E6: 1.3 | F6: 0.85 | G6: 0.85 | H6: 1 | I6: 0.9 | J6: 0.95 | K6: 0.9 | L6: 0.9 | M6: 1 | N6: 1 | O6: 1
A7: Кухонный комбайн AT-SM23
A8: Готовая партия (депозит 30% оплачен владельцем) | B8: шт. | C8: =Допущения!$B$39 -> 200 | D8: 0 | E8: 0 | F8: 0 | G8: 0 | H8: 0 | I8: 0 | J8: 0 | K8: 0 | L8: 0 | M8: 0 | N8: 0 | O8: 0 | P8: =SUM(C8:O8) -> 200
A9: Заказ у поставщика | B9: шт. | C9: 0 | D9: 0 | E9: 200 | F9: 0 | G9: 0 | H9: 0 | I9: 200 | J9: 0 | K9: 0 | L9: 0 | M9: 0 | N9: 0 | O9: 0 | P9: =SUM(C9:O9) -> 400
A10: Поступление на склад | B10: шт. | C10: =IF(0=1,C8,0) -> 0 | D10: =IF(1-0=Допущения!$B$32,C9,0)+IF(1=1,C8,0) -> 200 | E10: =IF(2-0=Допущения!$B$32,C9,0)+IF(2-1=Допущения!$B$32,D9,0)+IF(2=1,C8,0) -> 0 | F10: =IF(3-0=Допущения!$B$32,C9,0)+IF(3-1=Допущения!$B$32,D9,0)+IF(3-2=Допущения!$B$32,E9,0)+IF(3=1,C8,0) -> 0 | G10: =IF(4-0=Допущения!$B$32,C9,0)+IF(4-1=Допущения!$B$32,D9,0)+IF(4-2=Допущения!$B$32,E9,0)+IF(4-3=Допущения!$B$32,F9,0)+IF(4=1,C8,0) -> 0 | H10: =IF(5-0=Допущения!$B$32,C9,0)+IF(5-1=Допущения!$B$32,D9,0)+IF(5-2=Допущения!$B$32,E9,0)+IF(5-3=Допущения!$B$32,F9,0)+IF(5-4=Допущения!$B$32,G9,0)+IF(5=1,C8,0) -> 200 | I10: =IF(6-0=Допущения!$B$32,C9,0)+IF(6-1=Допущения!$B$32,D9,0)+IF(6-2=Допущения!$B$32,E9,0)+IF(6-3=Допущения!$B$32,F9,0)+IF(6-4=Допущения!$B$32,G9,0)+IF(6-5=Допущения!$B$32,H9,0)+IF(6=1,C8,0) -> 0 | J10: =IF(7-0=Допущения!$B$32,C9,0)+IF(7-1=Допущения!$B$32,D9,0)+IF(7-2=Допущения!$B$32,E9,0)+IF(7-3=Допущения!$B$32,F9,0)+IF(7-4=Допущения!$B$32,G9,0)+IF(7-5=Допущения!$B$32,H9,0)+IF(7-6=Допущения!$B$32,I9,0)+IF(7=1,C8,0) -> 0 | K10: =IF(8-0=Допущения!$B$32,C9,0)+IF(8-1=Допущения!$B$32,D9,0)+IF(8-2=Допущения!$B$32,E9,0)+IF(8-3=Допущения!$B$32,F9,0)+IF(8-4=Допущения!$B$32,G9,0)+IF(8-5=Допущения!$B$32,H9,0)+IF(8-6=Допущения!$B$32,I9,0)+IF(8-7=Допущения!$B$32,J9,0)+IF(8=1,C8,0) -> 0 | L10: =IF(9-0=Допущения!$B$32,C9,0)+IF(9-1=Допущения!$B$32,D9,0)+IF(9-2=Допущения!$B$32,E9,0)+IF(9-3=Допущения!$B$32,F9,0)+IF(9-4=Допущения!$B$32,G9,0)+IF(9-5=Допущения!$B$32,H9,0)+IF(9-6=Допущения!$B$32,I9,0)+IF(9-7=Допущения!$B$32,J9,0)+IF(9-8=Допущения!$B$32,K9,0)+IF(9=1,C8,0) -> 200 | M10: =IF(10-0=Допущения!$B$32,C9,0)+IF(10-1=Допущения!$B$32,D9,0)+IF(10-2=Допущения!$B$32,E9,0)+IF(10-3=Допущения!$B$32,F9,0)+IF(10-4=Допущения!$B$32,G9,0)+IF(10-5=Допущения!$B$32,H9,0)+IF(10-6=Допущения!$B$32,I9,0)+IF(10-7=Допущения!$B$32,J9,0)+IF(10-8=Допущения!$B$32,K9,0)+IF(10-9=Допущения!$B$32,L9,0)+IF(10=1,C8,0) -> 0 | N10: =IF(11-0=Допущения!$B$32,C9,0)+IF(11-1=Допущения!$B$32,D9,0)+IF(11-2=Допущения!$B$32,E9,0)+IF(11-3=Допущения!$B$32,F9,0)+IF(11-4=Допущения!$B$32,G9,0)+IF(11-5=Допущения!$B$32,H9,0)+IF(11-6=Допущения!$B$32,I9,0)+IF(11-7=Допущения!$B$32,J9,0)+IF(11-8=Допущения!$B$32,K9,0)+IF(11-9=Допущения!$B$32,L9,0)+IF(11-10=Допущения!$B$32,M9,0)+IF(11=1,C8,0) -> 0 | O10: =IF(12-0=Допущения!$B$32,C9,0)+IF(12-1=Допущения!$B$32,D9,0)+IF(12-2=Допущения!$B$32,E9,0)+IF(12-3=Допущения!$B$32,F9,0)+IF(12-4=Допущения!$B$32,G9,0)+IF(12-5=Допущения!$B$32,H9,0)+IF(12-6=Допущения!$B$32,I9,0)+IF(12-7=Допущения!$B$32,J9,0)+IF(12-8=Допущения!$B$32,K9,0)+IF(12-9=Допущения!$B$32,L9,0)+IF(12-10=Допущения!$B$32,M9,0)+IF(12-11=Допущения!$B$32,N9,0)+IF(12=1,C8,0) -> 0 | P10: =SUM(C10:O10) -> 600
A11: Остаток на начало месяца | B11: шт. | C11: 0 | D11: =C14 -> 0 | E11: =D14 -> 143 | F11: =E14 -> 78 | G11: =F14 -> 35 | H11: =G14 -> 0 | I11: =H14 -> 150 | J11: =I14 -> 105 | K11: =J14 -> 57 | ... O11: =N14 -> 67
A12: Спрос по плану | B12: шт. | C12: 0 | D12: =ROUND(Допущения!$B$26*D$6*Допущения!$B$20,0) -> 57 | E12: =ROUND(Допущения!$B$26*E$6*Допущения!$B$20,0) -> 65 | F12: =ROUND(Допущения!$B$26*F$6*Допущения!$B$20,0) -> 43 | G12: =ROUND(Допущения!$B$26*G$6*Допущения!$B$20,0) -> 43 | H12: =ROUND(Допущения!$B$26*H$6*Допущения!$B$20,0) -> 50 | I12: =ROUND(Допущения!$B$26*I$6*Допущения!$B$20,0) -> 45 | J12: =ROUND(Допущения!$B$26*J$6*Допущения!$B$20,0) -> 48 | K12: =ROUND(Допущения!$B$26*K$6*Допущения!$B$20,0) -> 45 | ... O12: =ROUND(Допущения!$B$26*O$6*Допущения!$B$20,0) -> 50 | P12: =SUM(C12:O12) -> 591
A13: Продажи (ограничены остатком) | B13: шт. | C13: =MIN(C12,C11+C10) -> 0 | D13: =MIN(D12,D11+D10) -> 57 | E13: =MIN(E12,E11+E10) -> 65 | F13: =MIN(F12,F11+F10) -> 43 | G13: =MIN(G12,G11+G10) -> 35 | H13: =MIN(H12,H11+H10) -> 50 | I13: =MIN(I12,I11+I10) -> 45 | J13: =MIN(J12,J11+J10) -> 48 | ... O13: =MIN(O12,O11+O10) -> 50 | P13: =SUM(C13:O13) -> 583
A14: Остаток на конец месяца | B14: шт. | C14: =C11+C10-C13 -> 0 | D14: =D11+D10-D13 -> 143 | E14: =E11+E10-E13 -> 78 | F14: =F11+F10-F13 -> 35 | G14: =G11+G10-G13 -> 0 | H14: =H11+H10-H13 -> 150 | I14: =I11+I10-I13 -> 105 | J14: =J11+J10-J13 -> 57 | ... O14: =O11+O10-O13 -> 17
A15: Выручка | B15: ₸ | C15: =C13*Допущения!$B$25 -> 0 | D15: =D13*Допущения!$B$25 -> 6356298 | E15: =E13*Допущения!$B$25 -> 7248410 | F15: =F13*Допущения!$B$25 -> 4795102 | G15: =G13*Допущения!$B$25 -> 3902990 | H15: =H13*Допущения!$B$25 -> 5575700 | I15: =I13*Допущения!$B$25 -> 5018130 | J15: =J13*Допущения!$B$25 -> 5352672 | ... O15: =O13*Допущения!$B$25 -> 5575700 | P15: =SUM(C15:O15) -> 65012662
A16: Оплата поставщику и карго | B16: ₸ | C16: =Допущения!$B$36*C9*Допущения!$B$24+Допущения!$B$6+Допущения!$B$7 -> 7500000 | D16: =Допущения!$B$36*D9*Допущения!$B$24+IF(1-0=Допущения!$B$31,(1-Допущения!$B$36)*C9*Допущения!$B$24,0) -> 0 | E16: =Допущения!$B$36*E9*Допущения!$B$24+IF(2-0=Допущения!$B$31,(1-Допущения!$B$36)*C9*Допущения!$B$24,0)+IF(2-1=Допущения!$B$31,(1-Допущения!$B$36)*D9*Допущения!$B$24,0) -> 3000000 | F16: =Допущения!$B$36*F9*Допущения!$B$24+IF(3-0=Допущения!$B$31,(1-Допущения!$B$36)*C9*Допущения!$B$24,0)+IF(3-1=Допущения!$B$31,(1-Допущения!$B$36)*D9*Допущения!$B$24,0)+IF(3-2=Допущения!$B$31,(1-Допущения!$B$36)*E9*Допущения!$B$24,0) -> 0 | G16: =Допущения!$B$36*G9*Допущения!$B$24+IF(4-0=Допущения!$B$31,(1-Допущения!$B$36)*C9*Допущения!$B$24,0)+IF(4-1=Допущения!$B$31,(1-Допущения!$B$36)*D9*Допущения!$B$24,0)+IF(4-2=Допущения!$B$31,(1-Допущения!$B$36)*E9*Допущения!$B$24,0)+IF(4-3=Допущения!$B$31,(1-Допущения!$B$36)*F9*Допущения!$B$24,0) -> 7000000 | H16: =Допущения!$B$36*H9*Допущения!$B$24+IF(5-0=Допущения!$B$31,(1-Допущения!$B$36)*C9*Допущения!$B$24,0)+IF(5-1=Допущения!$B$31,(1-Допущения!$B$36)*D9*Допущения!$B$24,0)+IF(5-2=Допущения!$B$31,(1-Допущения!$B$36)*E9*Допущения!$B$24,0)+IF(5-3=Допущения!$B$31,(1-Допущения!$B$36)*F9*Допущения!$B$24,0)+IF(5-4=Допущения!$B$31,(1-Допущения!$B$36)*G9*Допущения!$B$24,0) -> 0 | I16: =Допущения!$B$36*I9*Допущения!$B$24+IF(6-0=Допущения!$B$31,(1-Допущения!$B$36)*C9*Допущения!$B$24,0)+IF(6-1=Допущения!$B$31,(1-Допущения!$B$36)*D9*Допущения!$B$24,0)+IF(6-2=Допущения!$B$31,(1-Допущения!$B$36)*E9*Допущения!$B$24,0)+IF(6-3=Допущения!$B$31,(1-Допущения!$B$36)*F9*Допущения!$B$24,0)+IF(6-4=Допущения!$B$31,(1-Допущения!$B$36)*G9*Допущения!$B$24,0)+IF(6-5=Допущения!$B$31,(1-Допущения!$B$36)*H9*Допущения!$B$24,0) -> 3000000 | J16: =Допущения!$B$36*J9*Допущения!$B$24+IF(7-0=Допущения!$B$31,(1-Допущения!$B$36)*C9*Допущения!$B$24,0)+IF(7-1=Допущения!$B$31,(1-Допущения!$B$36)*D9*Допущения!$B$24,0)+IF(7-2=Допущения!$B$31,(1-Допущения!$B$36)*E9*Допущения!$B$24,0)+IF(7-3=Допущения!$B$31,(1-Допущения!$B$36)*F9*Допущения!$B$24,0)+IF(7-4=Допущения!$B$31,(1-Допущения!$B$36)*G9*Допущения!$B$24,0)+IF(7-5=Допущения!$B$31,(1-Допущения!$B$36)*H9*Допущения!$B$24,0)+IF(7-6=Допущения!$B$31,(1-Допущения!$B$36)*I9*Допущения!$B$24,0) -> 0 | K16: =Допущения!$B$36*K9*Допущения!$B$24+IF(8-0=Допущения!$B$31,(1-Допущения!$B$36)*C9*Допущения!$B$24,0)+IF(8-1=Допущения!$B$31,(1-Допущения!$B$36)*D9*Допущения!$B$24,0)+IF(8-2=Допущения!$B$31,(1-Допущения!$B$36)*E9*Допущения!$B$24,0)+IF(8-3=Допущения!$B$31,(1-Допущения!$B$36)*F9*Допущения!$B$24,0)+IF(8-4=Допущения!$B$31,(1-Допущения!$B$36)*G9*Допущения!$B$24,0)+IF(8-5=Допущения!$B$31,(1-Допущения!$B$36)*H9*Допущения!$B$24,0)+IF(8-6=Допущения!$B$31,(1-Допущения!$B$36)*I9*Допущения!$B$24,0)+IF(8-7=Допущения!$B$31,(1-Допущения!$B$36)*J9*Допущения!$B$24,0) -> 7000000 | L16: =Допущения!$B$36*L9*Допущения!$B$24+IF(9-0=Допущения!$B$31,(1-Допущения!$B$36)*C9*Допущения!$B$24,0)+IF(9-1=Допущения!$B$31,(1-Допущения!$B$36)*D9*Допущения!$B$24,0)+IF(9-2=Допущения!$B$31,(1-Допущения!$B$36)*E9*Допущения!$B$24,0)+IF(9-3=Допущения!$B$31,(1-Допущения!$B$36)*F9*Допущения!$B$24,0)+IF(9-4=Допущения!$B$31,(1-Допущения!$B$36)*G9*Допущения!$B$24,0)+IF(9-5=Допущения!$B$31,(1-Допущения!$B$36)*H9*Допущения!$B$24,0)+IF(9-6=Допущения!$B$31,(1-Допущения!$B$36)*I9*Допущения!$B$24,0)+IF(9-7=Допущения!$B$31,(1-Допущения!$B$36)*J9*Допущения!$B$24,0)+IF(9-8=Допущения!$B$31,(1-Допущения!$B$36)*K9*Допущения!$B$24,0) -> 0 | M16: =Допущения!$B$36*M9*Допущения!$B$24+IF(10-0=Допущения!$B$31,(1-Допущения!$B$36)*C9*Допущения!$B$24,0)+IF(10-1=Допущения!$B$31,(1-Допущения!$B$36)*D9*Допущения!$B$24,0)+IF(10-2=Допущения!$B$31,(1-Допущения!$B$36)*E9*Допущения!$B$24,0)+IF(10-3=Допущения!$B$31,(1-Допущения!$B$36)*F9*Допущения!$B$24,0)+IF(10-4=Допущения!$B$31,(1-Допущения!$B$36)*G9*Допущения!$B$24,0)+IF(10-5=Допущения!$B$31,(1-Допущения!$B$36)*H9*Допущения!$B$24,0)+IF(10-6=Допущения!$B$31,(1-Допущения!$B$36)*I9*Допущения!$B$24,0)+IF(10-7=Допущения!$B$31,(1-Допущения!$B$36)*J9*Допущения!$B$24,0)+IF(10-8=Допущения!$B$31,(1-Допущения!$B$36)*K9*Допущения!$B$24,0)+IF(10-9=Допущения!$B$31,(1-Допущения!$B$36)*L9*Допущения!$B$24,0) -> 0 | N16: =Допущения!$B$36*N9*Допущения!$B$24+IF(11-0=Допущения!$B$31,(1-Допущения!$B$36)*C9*Допущения!$B$24,0)+IF(11-1=Допущения!$B$31,(1-Допущения!$B$36)*D9*Допущения!$B$24,0)+IF(11-2=Допущения!$B$31,(1-Допущения!$B$36)*E9*Допущения!$B$24,0)+IF(11-3=Допущения!$B$31,(1-Допущения!$B$36)*F9*Допущения!$B$24,0)+IF(11-4=Допущения!$B$31,(1-Допущения!$B$36)*G9*Допущения!$B$24,0)+IF(11-5=Допущения!$B$31,(1-Допущения!$B$36)*H9*Допущения!$B$24,0)+IF(11-6=Допущения!$B$31,(1-Допущения!$B$36)*I9*Допущения!$B$24,0)+IF(11-7=Допущения!$B$31,(1-Допущения!$B$36)*J9*Допущения!$B$24,0)+IF(11-8=Допущения!$B$31,(1-Допущения!$B$36)*K9*Допущения!$B$24,0)+IF(11-9=Допущения!$B$31,(1-Допущения!$B$36)*L9*Допущения!$B$24,0)+IF(11-10=Допущения!$B$31,(1-Допущения!$B$36)*M9*Допущения!$B$24,0) -> 0 | O16: =Допущения!$B$36*O9*Допущения!$B$24+IF(12-0=Допущения!$B$31,(1-Допущения!$B$36)*C9*Допущения!$B$24,0)+IF(12-1=Допущения!$B$31,(1-Допущения!$B$36)*D9*Допущения!$B$24,0)+IF(12-2=Допущения!$B$31,(1-Допущения!$B$36)*E9*Допущения!$B$24,0)+IF(12-3=Допущения!$B$31,(1-Допущения!$B$36)*F9*Допущения!$B$24,0)+IF(12-4=Допущения!$B$31,(1-Допущения!$B$36)*G9*Допущения!$B$24,0)+IF(12-5=Допущения!$B$31,(1-Допущения!$B$36)*H9*Допущения!$B$24,0)+IF(12-6=Допущения!$B$31,(1-Допущения!$B$36)*I9*Допущения!$B$24,0)+IF(12-7=Допущения!$B$31,(1-Допущения!$B$36)*J9*Допущения!$B$24,0)+IF(12-8=Допущения!$B$31,(1-Допущения!$B$36)*K9*Допущения!$B$24,0)+IF(12-9=Допущения!$B$31,(1-Допущения!$B$36)*L9*Допущения!$B$24,0)+IF(12-10=Допущения!$B$31,(1-Допущения!$B$36)*M9*Допущения!$B$24,0)+IF(12-11=Допущения!$B$31,(1-Допущения!$B$36)*N9*Допущения!$B$24,0) -> 0 | P16: =SUM(C16:O16) -> 27500000
A17: Комиссия Kaspi + доставка + возвраты | B17: ₸ | C17: =C15*(Допущения!$B$27+Допущения!$B$30)+C13*Допущения!$B$29 -> 0 | D17: =D15*(Допущения!$B$27+Допущения!$B$30)+D13*Допущения!$B$29 -> 961810.93 | E17: =E15*(Допущения!$B$27+Допущения!$B$30)+E13*Допущения!$B$29 -> 1096801.9 | F17: =F15*(Допущения!$B$27+Допущения!$B$30)+F13*Допущения!$B$29 -> 725576.67 | G17: =G15*(Допущения!$B$27+Допущения!$B$30)+G13*Допущения!$B$29 -> 590585.66 | H17: =H15*(Допущения!$B$27+Допущения!$B$30)+H13*Допущения!$B$29 -> 843693.8 | I17: =I15*(Допущения!$B$27+Допущения!$B$30)+I13*Допущения!$B$29 -> 759324.42 | J17: =J15*(Допущения!$B$27+Допущения!$B$30)+J13*Допущения!$B$29 -> 809946.05 | ... O17: =O15*(Допущения!$B$27+Допущения!$B$30)+O13*Допущения!$B$29 -> 843693.8 | P17: =SUM(C17:O17) -> 9837469.7
A18: Валовая прибыль (выручка − себест. проданного − Kaspi) | B18: ₸ | C18: =C15-C13*Допущения!$B$24-C17 -> 0 | D18: =D15-D13*Допущения!$B$24-D17 -> 2544487.1 | E18: =E15-E13*Допущения!$B$24-E17 -> 2901608.1 | F18: =F15-F13*Допущения!$B$24-F17 -> 1919525.3 | G18: =G15-G13*Допущения!$B$24-G17 -> 1562404.3 | H18: =H15-H13*Допущения!$B$24-H17 -> 2232006.2 | I18: =I15-I13*Допущения!$B$24-I17 -> 2008805.6 | J18: =J15-J13*Допущения!$B$24-J17 -> 2142726 | ... O18: =O15-O13*Допущения!$B$24-O17 -> 2232006.2 | P18: =SUM(C18:O18) -> 26025192
A19: Подушка 35×60
A20: Заказ у поставщика | B20: шт. | C20: 150 | D20: 70 | E20: 100 | F20: 85 | G20: 100 | H20: 90 | I20: 95 | J20: 90 | K20: 90 | L20: 100 | M20: 100 | N20: 0 | O20: 0 | P20: =SUM(C20:O20) -> 1070
A21: Поступление на склад | B21: шт. | C21: =0 -> 0 | D21: =IF(1-0=Допущения!$C$32,C20,0) -> 0 | E21: =IF(2-0=Допущения!$C$32,C20,0)+IF(2-1=Допущения!$C$32,D20,0) -> 150 | F21: =IF(3-0=Допущения!$C$32,C20,0)+IF(3-1=Допущения!$C$32,D20,0)+IF(3-2=Допущения!$C$32,E20,0) -> 70 | G21: =IF(4-0=Допущения!$C$32,C20,0)+IF(4-1=Допущения!$C$32,D20,0)+IF(4-2=Допущения!$C$32,E20,0)+IF(4-3=Допущения!$C$32,F20,0) -> 100 | H21: =IF(5-0=Допущения!$C$32,C20,0)+IF(5-1=Допущения!$C$32,D20,0)+IF(5-2=Допущения!$C$32,E20,0)+IF(5-3=Допущения!$C$32,F20,0)+IF(5-4=Допущения!$C$32,G20,0) -> 85 | I21: =IF(6-0=Допущения!$C$32,C20,0)+IF(6-1=Допущения!$C$32,D20,0)+IF(6-2=Допущения!$C$32,E20,0)+IF(6-3=Допущения!$C$32,F20,0)+IF(6-4=Допущения!$C$32,G20,0)+IF(6-5=Допущения!$C$32,H20,0) -> 100 | J21: =IF(7-0=Допущения!$C$32,C20,0)+IF(7-1=Допущения!$C$32,D20,0)+IF(7-2=Допущения!$C$32,E20,0)+IF(7-3=Допущения!$C$32,F20,0)+IF(7-4=Допущения!$C$32,G20,0)+IF(7-5=Допущения!$C$32,H20,0)+IF(7-6=Допущения!$C$32,I20,0) -> 90 | K21: =IF(8-0=Допущения!$C$32,C20,0)+IF(8-1=Допущения!$C$32,D20,0)+IF(8-2=Допущения!$C$32,E20,0)+IF(8-3=Допущения!$C$32,F20,0)+IF(8-4=Допущения!$C$32,G20,0)+IF(8-5=Допущения!$C$32,H20,0)+IF(8-6=Допущения!$C$32,I20,0)+IF(8-7=Допущения!$C$32,J20,0) -> 95 | L21: =IF(9-0=Допущения!$C$32,C20,0)+IF(9-1=Допущения!$C$32,D20,0)+IF(9-2=Допущения!$C$32,E20,0)+IF(9-3=Допущения!$C$32,F20,0)+IF(9-4=Допущения!$C$32,G20,0)+IF(9-5=Допущения!$C$32,H20,0)+IF(9-6=Допущения!$C$32,I20,0)+IF(9-7=Допущения!$C$32,J20,0)+IF(9-8=Допущения!$C$32,K20,0) -> 90 | M21: =IF(10-0=Допущения!$C$32,C20,0)+IF(10-1=Допущения!$C$32,D20,0)+IF(10-2=Допущения!$C$32,E20,0)+IF(10-3=Допущения!$C$32,F20,0)+IF(10-4=Допущения!$C$32,G20,0)+IF(10-5=Допущения!$C$32,H20,0)+IF(10-6=Допущения!$C$32,I20,0)+IF(10-7=Допущения!$C$32,J20,0)+IF(10-8=Допущения!$C$32,K20,0)+IF(10-9=Допущения!$C$32,L20,0) -> 90 | N21: =IF(11-0=Допущения!$C$32,C20,0)+IF(11-1=Допущения!$C$32,D20,0)+IF(11-2=Допущения!$C$32,E20,0)+IF(11-3=Допущения!$C$32,F20,0)+IF(11-4=Допущения!$C$32,G20,0)+IF(11-5=Допущения!$C$32,H20,0)+IF(11-6=Допущения!$C$32,I20,0)+IF(11-7=Допущения!$C$32,J20,0)+IF(11-8=Допущения!$C$32,K20,0)+IF(11-9=Допущения!$C$32,L20,0)+IF(11-10=Допущения!$C$32,M20,0) -> 100 | O21: =IF(12-0=Допущения!$C$32,C20,0)+IF(12-1=Допущения!$C$32,D20,0)+IF(12-2=Допущения!$C$32,E20,0)+IF(12-3=Допущения!$C$32,F20,0)+IF(12-4=Допущения!$C$32,G20,0)+IF(12-5=Допущения!$C$32,H20,0)+IF(12-6=Допущения!$C$32,I20,0)+IF(12-7=Допущения!$C$32,J20,0)+IF(12-8=Допущения!$C$32,K20,0)+IF(12-9=Допущения!$C$32,L20,0)+IF(12-10=Допущения!$C$32,M20,0)+IF(12-11=Допущения!$C$32,N20,0) -> 100 | P21: =SUM(C21:O21) -> 1070
A22: Остаток на начало месяца | B22: шт. | C22: 0 | D22: =C25 -> 0 | E22: =D25 -> 0 | F22: =E25 -> 20 | G22: =F25 -> 5 | H22: =G25 -> 20 | I22: =H25 -> 5 | J22: =I25 -> 15 | K22: =J25 -> 10 | ... O22: =N25 -> 5
A23: Спрос по плану | B23: шт. | C23: 0 | D23: =ROUND(Допущения!$C$26*D$6*Допущения!$B$20,0) -> 115 | E23: =ROUND(Допущения!$C$26*E$6*Допущения!$B$20,0) -> 130 | F23: =ROUND(Допущения!$C$26*F$6*Допущения!$B$20,0) -> 85 | G23: =ROUND(Допущения!$C$26*G$6*Допущения!$B$20,0) -> 85 | H23: =ROUND(Допущения!$C$26*H$6*Допущения!$B$20,0) -> 100 | I23: =ROUND(Допущения!$C$26*I$6*Допущения!$B$20,0) -> 90 | J23: =ROUND(Допущения!$C$26*J$6*Допущения!$B$20,0) -> 95 | K23: =ROUND(Допущения!$C$26*K$6*Допущения!$B$20,0) -> 90 | ... O23: =ROUND(Допущения!$C$26*O$6*Допущения!$B$20,0) -> 100 | P23: =SUM(C23:O23) -> 1180
A24: Продажи (ограничены остатком) | B24: шт. | C24: =MIN(C23,C22+C21) -> 0 | D24: =MIN(D23,D22+D21) -> 0 | E24: =MIN(E23,E22+E21) -> 130 | F24: =MIN(F23,F22+F21) -> 85 | G24: =MIN(G23,G22+G21) -> 85 | H24: =MIN(H23,H22+H21) -> 100 | I24: =MIN(I23,I22+I21) -> 90 | J24: =MIN(J23,J22+J21) -> 95 | ... O24: =MIN(O23,O22+O21) -> 100 | P24: =SUM(C24:O24) -> 1065
A25: Остаток на конец месяца | B25: шт. | C25: =C22+C21-C24 -> 0 | D25: =D22+D21-D24 -> 0 | E25: =E22+E21-E24 -> 20 | F25: =F22+F21-F24 -> 5 | G25: =G22+G21-G24 -> 20 | H25: =H22+H21-H24 -> 5 | I25: =I22+I21-I24 -> 15 | J25: =J22+J21-J24 -> 10 | ... O25: =O22+O21-O24 -> 5
A26: Выручка | B26: ₸ | C26: =C24*Допущения!$C$25 -> 0 | D26: =D24*Допущения!$C$25 -> 0 | E26: =E24*Допущения!$C$25 -> 1474720 | F26: =F24*Допущения!$C$25 -> 964240 | G26: =G24*Допущения!$C$25 -> 964240 | H26: =H24*Допущения!$C$25 -> 1134400 | I26: =I24*Допущения!$C$25 -> 1020960 | J26: =J24*Допущения!$C$25 -> 1077680 | ... O26: =O24*Допущения!$C$25 -> 1134400 | P26: =SUM(C26:O26) -> 12081360
A27: Оплата поставщику и карго | B27: ₸ | C27: =Допущения!$B$36*C20*Допущения!$C$24 -> 180000 | D27: =Допущения!$B$36*D20*Допущения!$C$24+IF(1-0=Допущения!$C$31,(1-Допущения!$B$36)*C20*Допущения!$C$24,0) -> 504000 | E27: =Допущения!$B$36*E20*Допущения!$C$24+IF(2-0=Допущения!$C$31,(1-Допущения!$B$36)*C20*Допущения!$C$24,0)+IF(2-1=Допущения!$C$31,(1-Допущения!$B$36)*D20*Допущения!$C$24,0) -> 316000 | F27: =Допущения!$B$36*F20*Допущения!$C$24+IF(3-0=Допущения!$C$31,(1-Допущения!$B$36)*C20*Допущения!$C$24,0)+IF(3-1=Допущения!$C$31,(1-Допущения!$B$36)*D20*Допущения!$C$24,0)+IF(3-2=Допущения!$C$31,(1-Допущения!$B$36)*E20*Допущения!$C$24,0) -> 382000 | G27: =Допущения!$B$36*G20*Допущения!$C$24+IF(4-0=Допущения!$C$31,(1-Допущения!$B$36)*C20*Допущения!$C$24,0)+IF(4-1=Допущения!$C$31,(1-Допущения!$B$36)*D20*Допущения!$C$24,0)+IF(4-2=Допущения!$C$31,(1-Допущения!$B$36)*E20*Допущения!$C$24,0)+IF(4-3=Допущения!$C$31,(1-Допущения!$B$36)*F20*Допущения!$C$24,0) -> 358000 | H27: =Допущения!$B$36*H20*Допущения!$C$24+IF(5-0=Допущения!$C$31,(1-Допущения!$B$36)*C20*Допущения!$C$24,0)+IF(5-1=Допущения!$C$31,(1-Допущения!$B$36)*D20*Допущения!$C$24,0)+IF(5-2=Допущения!$C$31,(1-Допущения!$B$36)*E20*Допущения!$C$24,0)+IF(5-3=Допущения!$C$31,(1-Допущения!$B$36)*F20*Допущения!$C$24,0)+IF(5-4=Допущения!$C$31,(1-Допущения!$B$36)*G20*Допущения!$C$24,0) -> 388000 | I27: =Допущения!$B$36*I20*Допущения!$C$24+IF(6-0=Допущения!$C$31,(1-Допущения!$B$36)*C20*Допущения!$C$24,0)+IF(6-1=Допущения!$C$31,(1-Допущения!$B$36)*D20*Допущения!$C$24,0)+IF(6-2=Допущения!$C$31,(1-Допущения!$B$36)*E20*Допущения!$C$24,0)+IF(6-3=Допущения!$C$31,(1-Допущения!$B$36)*F20*Допущения!$C$24,0)+IF(6-4=Допущения!$C$31,(1-Допущения!$B$36)*G20*Допущения!$C$24,0)+IF(6-5=Допущения!$C$31,(1-Допущения!$B$36)*H20*Допущения!$C$24,0) -> 366000 | J27: =Допущения!$B$36*J20*Допущения!$C$24+IF(7-0=Допущения!$C$31,(1-Допущения!$B$36)*C20*Допущения!$C$24,0)+IF(7-1=Допущения!$C$31,(1-Допущения!$B$36)*D20*Допущения!$C$24,0)+IF(7-2=Допущения!$C$31,(1-Допущения!$B$36)*E20*Допущения!$C$24,0)+IF(7-3=Допущения!$C$31,(1-Допущения!$B$36)*F20*Допущения!$C$24,0)+IF(7-4=Допущения!$C$31,(1-Допущения!$B$36)*G20*Допущения!$C$24,0)+IF(7-5=Допущения!$C$31,(1-Допущения!$B$36)*H20*Допущения!$C$24,0)+IF(7-6=Допущения!$C$31,(1-Допущения!$B$36)*I20*Допущения!$C$24,0) -> 374000 | K27: =Допущения!$B$36*K20*Допущения!$C$24+IF(8-0=Допущения!$C$31,(1-Допущения!$B$36)*C20*Допущения!$C$24,0)+IF(8-1=Допущения!$C$31,(1-Допущения!$B$36)*D20*Допущения!$C$24,0)+IF(8-2=Допущения!$C$31,(1-Допущения!$B$36)*E20*Допущения!$C$24,0)+IF(8-3=Допущения!$C$31,(1-Допущения!$B$36)*F20*Допущения!$C$24,0)+IF(8-4=Допущения!$C$31,(1-Допущения!$B$36)*G20*Допущения!$C$24,0)+IF(8-5=Допущения!$C$31,(1-Допущения!$B$36)*H20*Допущения!$C$24,0)+IF(8-6=Допущения!$C$31,(1-Допущения!$B$36)*I20*Допущения!$C$24,0)+IF(8-7=Допущения!$C$31,(1-Допущения!$B$36)*J20*Допущения!$C$24,0) -> 360000 | L27: =Допущения!$B$36*L20*Допущения!$C$24+IF(9-0=Допущения!$C$31,(1-Допущения!$B$36)*C20*Допущения!$C$24,0)+IF(9-1=Допущения!$C$31,(1-Допущения!$B$36)*D20*Допущения!$C$24,0)+IF(9-2=Допущения!$C$31,(1-Допущения!$B$36)*E20*Допущения!$C$24,0)+IF(9-3=Допущения!$C$31,(1-Допущения!$B$36)*F20*Допущения!$C$24,0)+IF(9-4=Допущения!$C$31,(1-Допущения!$B$36)*G20*Допущения!$C$24,0)+IF(9-5=Допущения!$C$31,(1-Допущения!$B$36)*H20*Допущения!$C$24,0)+IF(9-6=Допущения!$C$31,(1-Допущения!$B$36)*I20*Допущения!$C$24,0)+IF(9-7=Допущения!$C$31,(1-Допущения!$B$36)*J20*Допущения!$C$24,0)+IF(9-8=Допущения!$C$31,(1-Допущения!$B$36)*K20*Допущения!$C$24,0) -> 372000 | M27: =Допущения!$B$36*M20*Допущения!$C$24+IF(10-0=Допущения!$C$31,(1-Допущения!$B$36)*C20*Допущения!$C$24,0)+IF(10-1=Допущения!$C$31,(1-Допущения!$B$36)*D20*Допущения!$C$24,0)+IF(10-2=Допущения!$C$31,(1-Допущения!$B$36)*E20*Допущения!$C$24,0)+IF(10-3=Допущения!$C$31,(1-Допущения!$B$36)*F20*Допущения!$C$24,0)+IF(10-4=Допущения!$C$31,(1-Допущения!$B$36)*G20*Допущения!$C$24,0)+IF(10-5=Допущения!$C$31,(1-Допущения!$B$36)*H20*Допущения!$C$24,0)+IF(10-6=Допущения!$C$31,(1-Допущения!$B$36)*I20*Допущения!$C$24,0)+IF(10-7=Допущения!$C$31,(1-Допущения!$B$36)*J20*Допущения!$C$24,0)+IF(10-8=Допущения!$C$31,(1-Допущения!$B$36)*K20*Допущения!$C$24,0)+IF(10-9=Допущения!$C$31,(1-Допущения!$B$36)*L20*Допущения!$C$24,0) -> 400000 | N27: =Допущения!$B$36*N20*Допущения!$C$24+IF(11-0=Допущения!$C$31,(1-Допущения!$B$36)*C20*Допущения!$C$24,0)+IF(11-1=Допущения!$C$31,(1-Допущения!$B$36)*D20*Допущения!$C$24,0)+IF(11-2=Допущения!$C$31,(1-Допущения!$B$36)*E20*Допущения!$C$24,0)+IF(11-3=Допущения!$C$31,(1-Допущения!$B$36)*F20*Допущения!$C$24,0)+IF(11-4=Допущения!$C$31,(1-Допущения!$B$36)*G20*Допущения!$C$24,0)+IF(11-5=Допущения!$C$31,(1-Допущения!$B$36)*H20*Допущения!$C$24,0)+IF(11-6=Допущения!$C$31,(1-Допущения!$B$36)*I20*Допущения!$C$24,0)+IF(11-7=Допущения!$C$31,(1-Допущения!$B$36)*J20*Допущения!$C$24,0)+IF(11-8=Допущения!$C$31,(1-Допущения!$B$36)*K20*Допущения!$C$24,0)+IF(11-9=Допущения!$C$31,(1-Допущения!$B$36)*L20*Допущения!$C$24,0)+IF(11-10=Допущения!$C$31,(1-Допущения!$B$36)*M20*Допущения!$C$24,0) -> 280000 | O27: =Допущения!$B$36*O20*Допущения!$C$24+IF(12-0=Допущения!$C$31,(1-Допущения!$B$36)*C20*Допущения!$C$24,0)+IF(12-1=Допущения!$C$31,(1-Допущения!$B$36)*D20*Допущения!$C$24,0)+IF(12-2=Допущения!$C$31,(1-Допущения!$B$36)*E20*Допущения!$C$24,0)+IF(12-3=Допущения!$C$31,(1-Допущения!$B$36)*F20*Допущения!$C$24,0)+IF(12-4=Допущения!$C$31,(1-Допущения!$B$36)*G20*Допущения!$C$24,0)+IF(12-5=Допущения!$C$31,(1-Допущения!$B$36)*H20*Допущения!$C$24,0)+IF(12-6=Допущения!$C$31,(1-Допущения!$B$36)*I20*Допущения!$C$24,0)+IF(12-7=Допущения!$C$31,(1-Допущения!$B$36)*J20*Допущения!$C$24,0)+IF(12-8=Допущения!$C$31,(1-Допущения!$B$36)*K20*Допущения!$C$24,0)+IF(12-9=Допущения!$C$31,(1-Допущения!$B$36)*L20*Допущения!$C$24,0)+IF(12-10=Допущения!$C$31,(1-Допущения!$B$36)*M20*Допущения!$C$24,0)+IF(12-11=Допущения!$C$31,(1-Допущения!$B$36)*N20*Допущения!$C$24,0) -> 0 | P27: =SUM(C27:O27) -> 4280000
A28: Комиссия Kaspi + доставка + возвраты | B28: ₸ | C28: =C26*(Допущения!$C$27+Допущения!$C$30)+C24*Допущения!$C$29 -> 0 | D28: =D26*(Допущения!$C$27+Допущения!$C$30)+D24*Допущения!$C$29 -> 0 | E28: =E26*(Допущения!$C$27+Допущения!$C$30)+E24*Допущения!$C$29 -> 303756.96 | F28: =F26*(Допущения!$C$27+Допущения!$C$30)+F24*Допущения!$C$29 -> 198610.32 | G28: =G26*(Допущения!$C$27+Допущения!$C$30)+G24*Допущения!$C$29 -> 198610.32 | H28: =H26*(Допущения!$C$27+Допущения!$C$30)+H24*Допущения!$C$29 -> 233659.2 | I28: =I26*(Допущения!$C$27+Допущения!$C$30)+I24*Допущения!$C$29 -> 210293.28 | J28: =J26*(Допущения!$C$27+Допущения!$C$30)+J24*Допущения!$C$29 -> 221976.24 | ... O28: =O26*(Допущения!$C$27+Допущения!$C$30)+O24*Допущения!$C$29 -> 233659.2 | P28: =SUM(C28:O28) -> 2488470.5
A29: Валовая прибыль (выручка − себест. проданного − Kaspi) | B29: ₸ | C29: =C26-C24*Допущения!$C$24-C28 -> 0 | D29: =D26-D24*Допущения!$C$24-D28 -> 0 | E29: =E26-E24*Допущения!$C$24-E28 -> 650963.04 | F29: =F26-F24*Допущения!$C$24-F28 -> 425629.68 | G29: =G26-G24*Допущения!$C$24-G28 -> 425629.68 | H29: =H26-H24*Допущения!$C$24-H28 -> 500740.8 | I29: =I26-I24*Допущения!$C$24-I28 -> 450666.72 | J29: =J26-J24*Допущения!$C$24-J28 -> 475703.76 | ... O29: =O26-O24*Допущения!$C$24-O28 -> 500740.8 | P29: =SUM(C29:O29) -> 5332889.5
A30: Подушка 40×60
A31: Заказ у поставщика | B31: шт. | C31: 150 | D31: 70 | E31: 100 | F31: 85 | G31: 100 | H31: 90 | I31: 95 | J31: 90 | K31: 90 | L31: 100 | M31: 100 | N31: 0 | O31: 0 | P31: =SUM(C31:O31) -> 1070
A32: Поступление на склад | B32: шт. | C32: =0 -> 0 | D32: =IF(1-0=Допущения!$D$32,C31,0) -> 0 | E32: =IF(2-0=Допущения!$D$32,C31,0)+IF(2-1=Допущения!$D$32,D31,0) -> 150 | F32: =IF(3-0=Допущения!$D$32,C31,0)+IF(3-1=Допущения!$D$32,D31,0)+IF(3-2=Допущения!$D$32,E31,0) -> 70 | G32: =IF(4-0=Допущения!$D$32,C31,0)+IF(4-1=Допущения!$D$32,D31,0)+IF(4-2=Допущения!$D$32,E31,0)+IF(4-3=Допущения!$D$32,F31,0) -> 100 | H32: =IF(5-0=Допущения!$D$32,C31,0)+IF(5-1=Допущения!$D$32,D31,0)+IF(5-2=Допущения!$D$32,E31,0)+IF(5-3=Допущения!$D$32,F31,0)+IF(5-4=Допущения!$D$32,G31,0) -> 85 | I32: =IF(6-0=Допущения!$D$32,C31,0)+IF(6-1=Допущения!$D$32,D31,0)+IF(6-2=Допущения!$D$32,E31,0)+IF(6-3=Допущения!$D$32,F31,0)+IF(6-4=Допущения!$D$32,G31,0)+IF(6-5=Допущения!$D$32,H31,0) -> 100 | J32: =IF(7-0=Допущения!$D$32,C31,0)+IF(7-1=Допущения!$D$32,D31,0)+IF(7-2=Допущения!$D$32,E31,0)+IF(7-3=Допущения!$D$32,F31,0)+IF(7-4=Допущения!$D$32,G31,0)+IF(7-5=Допущения!$D$32,H31,0)+IF(7-6=Допущения!$D$32,I31,0) -> 90 | K32: =IF(8-0=Допущения!$D$32,C31,0)+IF(8-1=Допущения!$D$32,D31,0)+IF(8-2=Допущения!$D$32,E31,0)+IF(8-3=Допущения!$D$32,F31,0)+IF(8-4=Допущения!$D$32,G31,0)+IF(8-5=Допущения!$D$32,H31,0)+IF(8-6=Допущения!$D$32,I31,0)+IF(8-7=Допущения!$D$32,J31,0) -> 95 | L32: =IF(9-0=Допущения!$D$32,C31,0)+IF(9-1=Допущения!$D$32,D31,0)+IF(9-2=Допущения!$D$32,E31,0)+IF(9-3=Допущения!$D$32,F31,0)+IF(9-4=Допущения!$D$32,G31,0)+IF(9-5=Допущения!$D$32,H31,0)+IF(9-6=Допущения!$D$32,I31,0)+IF(9-7=Допущения!$D$32,J31,0)+IF(9-8=Допущения!$D$32,K31,0) -> 90 | M32: =IF(10-0=Допущения!$D$32,C31,0)+IF(10-1=Допущения!$D$32,D31,0)+IF(10-2=Допущения!$D$32,E31,0)+IF(10-3=Допущения!$D$32,F31,0)+IF(10-4=Допущения!$D$32,G31,0)+IF(10-5=Допущения!$D$32,H31,0)+IF(10-6=Допущения!$D$32,I31,0)+IF(10-7=Допущения!$D$32,J31,0)+IF(10-8=Допущения!$D$32,K31,0)+IF(10-9=Допущения!$D$32,L31,0) -> 90 | N32: =IF(11-0=Допущения!$D$32,C31,0)+IF(11-1=Допущения!$D$32,D31,0)+IF(11-2=Допущения!$D$32,E31,0)+IF(11-3=Допущения!$D$32,F31,0)+IF(11-4=Допущения!$D$32,G31,0)+IF(11-5=Допущения!$D$32,H31,0)+IF(11-6=Допущения!$D$32,I31,0)+IF(11-7=Допущения!$D$32,J31,0)+IF(11-8=Допущения!$D$32,K31,0)+IF(11-9=Допущения!$D$32,L31,0)+IF(11-10=Допущения!$D$32,M31,0) -> 100 | O32: =IF(12-0=Допущения!$D$32,C31,0)+IF(12-1=Допущения!$D$32,D31,0)+IF(12-2=Допущения!$D$32,E31,0)+IF(12-3=Допущения!$D$32,F31,0)+IF(12-4=Допущения!$D$32,G31,0)+IF(12-5=Допущения!$D$32,H31,0)+IF(12-6=Допущения!$D$32,I31,0)+IF(12-7=Допущения!$D$32,J31,0)+IF(12-8=Допущения!$D$32,K31,0)+IF(12-9=Допущения!$D$32,L31,0)+IF(12-10=Допущения!$D$32,M31,0)+IF(12-11=Допущения!$D$32,N31,0) -> 100 | P32: =SUM(C32:O32) -> 1070
A33: Остаток на начало месяца | B33: шт. | C33: 0 | D33: =C36 -> 0 | E33: =D36 -> 0 | F33: =E36 -> 20 | G33: =F36 -> 5 | H33: =G36 -> 20 | I33: =H36 -> 5 | J33: =I36 -> 15 | K33: =J36 -> 10 | ... O33: =N36 -> 5
A34: Спрос по плану | B34: шт. | C34: 0 | D34: =ROUND(Допущения!$D$26*D$6*Допущения!$B$20,0) -> 115 | E34: =ROUND(Допущения!$D$26*E$6*Допущения!$B$20,0) -> 130 | F34: =ROUND(Допущения!$D$26*F$6*Допущения!$B$20,0) -> 85 | G34: =ROUND(Допущения!$D$26*G$6*Допущения!$B$20,0) -> 85 | H34: =ROUND(Допущения!$D$26*H$6*Допущения!$B$20,0) -> 100 | I34: =ROUND(Допущения!$D$26*I$6*Допущения!$B$20,0) -> 90 | J34: =ROUND(Допущения!$D$26*J$6*Допущения!$B$20,0) -> 95 | K34: =ROUND(Допущения!$D$26*K$6*Допущения!$B$20,0) -> 90 | ... O34: =ROUND(Допущения!$D$26*O$6*Допущения!$B$20,0) -> 100 | P34: =SUM(C34:O34) -> 1180
A35: Продажи (ограничены остатком) | B35: шт. | C35: =MIN(C34,C33+C32) -> 0 | D35: =MIN(D34,D33+D32) -> 0 | E35: =MIN(E34,E33+E32) -> 130 | F35: =MIN(F34,F33+F32) -> 85 | G35: =MIN(G34,G33+G32) -> 85 | H35: =MIN(H34,H33+H32) -> 100 | I35: =MIN(I34,I33+I32) -> 90 | J35: =MIN(J34,J33+J32) -> 95 | ... O35: =MIN(O34,O33+O32) -> 100 | P35: =SUM(C35:O35) -> 1065
A36: Остаток на конец месяца | B36: шт. | C36: =C33+C32-C35 -> 0 | D36: =D33+D32-D35 -> 0 | E36: =E33+E32-E35 -> 20 | F36: =F33+F32-F35 -> 5 | G36: =G33+G32-G35 -> 20 | H36: =H33+H32-H35 -> 5 | I36: =I33+I32-I35 -> 15 | J36: =J33+J32-J35 -> 10 | ... O36: =O33+O32-O35 -> 5
A37: Выручка | B37: ₸ | C37: =C35*Допущения!$D$25 -> 0 | D37: =D35*Допущения!$D$25 -> 0 | E37: =E35*Допущения!$D$25 -> 1895140 | F37: =F35*Допущения!$D$25 -> 1239130 | G37: =G35*Допущения!$D$25 -> 1239130 | H37: =H35*Допущения!$D$25 -> 1457800 | I37: =I35*Допущения!$D$25 -> 1312020 | J37: =J35*Допущения!$D$25 -> 1384910 | ... O37: =O35*Допущения!$D$25 -> 1457800 | P37: =SUM(C37:O37) -> 15525570
A38: Оплата поставщику и карго | B38: ₸ | C38: =Допущения!$B$36*C31*Допущения!$D$24 -> 225000 | D38: =Допущения!$B$36*D31*Допущения!$D$24+IF(1-0=Допущения!$D$31,(1-Допущения!$B$36)*C31*Допущения!$D$24,0) -> 630000 | E38: =Допущения!$B$36*E31*Допущения!$D$24+IF(2-0=Допущения!$D$31,(1-Допущения!$B$36)*C31*Допущения!$D$24,0)+IF(2-1=Допущения!$D$31,(1-Допущения!$B$36)*D31*Допущения!$D$24,0) -> 395000 | F38: =Допущения!$B$36*F31*Допущения!$D$24+IF(3-0=Допущения!$D$31,(1-Допущения!$B$36)*C31*Допущения!$D$24,0)+IF(3-1=Допущения!$D$31,(1-Допущения!$B$36)*D31*Допущения!$D$24,0)+IF(3-2=Допущения!$D$31,(1-Допущения!$B$36)*E31*Допущения!$D$24,0) -> 477500 | G38: =Допущения!$B$36*G31*Допущения!$D$24+IF(4-0=Допущения!$D$31,(1-Допущения!$B$36)*C31*Допущения!$D$24,0)+IF(4-1=Допущения!$D$31,(1-Допущения!$B$36)*D31*Допущения!$D$24,0)+IF(4-2=Допущения!$D$31,(1-Допущения!$B$36)*E31*Допущения!$D$24,0)+IF(4-3=Допущения!$D$31,(1-Допущения!$B$36)*F31*Допущения!$D$24,0) -> 447500 | H38: =Допущения!$B$36*H31*Допущения!$D$24+IF(5-0=Допущения!$D$31,(1-Допущения!$B$36)*C31*Допущения!$D$24,0)+IF(5-1=Допущения!$D$31,(1-Допущения!$B$36)*D31*Допущения!$D$24,0)+IF(5-2=Допущения!$D$31,(1-Допущения!$B$36)*E31*Допущения!$D$24,0)+IF(5-3=Допущения!$D$31,(1-Допущения!$B$36)*F31*Допущения!$D$24,0)+IF(5-4=Допущения!$D$31,(1-Допущения!$B$36)*G31*Допущения!$D$24,0) -> 485000 | I38: =Допущения!$B$36*I31*Допущения!$D$24+IF(6-0=Допущения!$D$31,(1-Допущения!$B$36)*C31*Допущения!$D$24,0)+IF(6-1=Допущения!$D$31,(1-Допущения!$B$36)*D31*Допущения!$D$24,0)+IF(6-2=Допущения!$D$31,(1-Допущения!$B$36)*E31*Допущения!$D$24,0)+IF(6-3=Допущения!$D$31,(1-Допущения!$B$36)*F31*Допущения!$D$24,0)+IF(6-4=Допущения!$D$31,(1-Допущения!$B$36)*G31*Допущения!$D$24,0)+IF(6-5=Допущения!$D$31,(1-Допущения!$B$36)*H31*Допущения!$D$24,0) -> 457500 | J38: =Допущения!$B$36*J31*Допущения!$D$24+IF(7-0=Допущения!$D$31,(1-Допущения!$B$36)*C31*Допущения!$D$24,0)+IF(7-1=Допущения!$D$31,(1-Допущения!$B$36)*D31*Допущения!$D$24,0)+IF(7-2=Допущения!$D$31,(1-Допущения!$B$36)*E31*Допущения!$D$24,0)+IF(7-3=Допущения!$D$31,(1-Допущения!$B$36)*F31*Допущения!$D$24,0)+IF(7-4=Допущения!$D$31,(1-Допущения!$B$36)*G31*Допущения!$D$24,0)+IF(7-5=Допущения!$D$31,(1-Допущения!$B$36)*H31*Допущения!$D$24,0)+IF(7-6=Допущения!$D$31,(1-Допущения!$B$36)*I31*Допущения!$D$24,0) -> 467500 | K38: =Допущения!$B$36*K31*Допущения!$D$24+IF(8-0=Допущения!$D$31,(1-Допущения!$B$36)*C31*Допущения!$D$24,0)+IF(8-1=Допущения!$D$31,(1-Допущения!$B$36)*D31*Допущения!$D$24,0)+IF(8-2=Допущения!$D$31,(1-Допущения!$B$36)*E31*Допущения!$D$24,0)+IF(8-3=Допущения!$D$31,(1-Допущения!$B$36)*F31*Допущения!$D$24,0)+IF(8-4=Допущения!$D$31,(1-Допущения!$B$36)*G31*Допущения!$D$24,0)+IF(8-5=Допущения!$D$31,(1-Допущения!$B$36)*H31*Допущения!$D$24,0)+IF(8-6=Допущения!$D$31,(1-Допущения!$B$36)*I31*Допущения!$D$24,0)+IF(8-7=Допущения!$D$31,(1-Допущения!$B$36)*J31*Допущения!$D$24,0) -> 450000 | L38: =Допущения!$B$36*L31*Допущения!$D$24+IF(9-0=Допущения!$D$31,(1-Допущения!$B$36)*C31*Допущения!$D$24,0)+IF(9-1=Допущения!$D$31,(1-Допущения!$B$36)*D31*Допущения!$D$24,0)+IF(9-2=Допущения!$D$31,(1-Допущения!$B$36)*E31*Допущения!$D$24,0)+IF(9-3=Допущения!$D$31,(1-Допущения!$B$36)*F31*Допущения!$D$24,0)+IF(9-4=Допущения!$D$31,(1-Допущения!$B$36)*G31*Допущения!$D$24,0)+IF(9-5=Допущения!$D$31,(1-Допущения!$B$36)*H31*Допущения!$D$24,0)+IF(9-6=Допущения!$D$31,(1-Допущения!$B$36)*I31*Допущения!$D$24,0)+IF(9-7=Допущения!$D$31,(1-Допущения!$B$36)*J31*Допущения!$D$24,0)+IF(9-8=Допущения!$D$31,(1-Допущения!$B$36)*K31*Допущения!$D$24,0) -> 465000 | M38: =Допущения!$B$36*M31*Допущения!$D$24+IF(10-0=Допущения!$D$31,(1-Допущения!$B$36)*C31*Допущения!$D$24,0)+IF(10-1=Допущения!$D$31,(1-Допущения!$B$36)*D31*Допущения!$D$24,0)+IF(10-2=Допущения!$D$31,(1-Допущения!$B$36)*E31*Допущения!$D$24,0)+IF(10-3=Допущения!$D$31,(1-Допущения!$B$36)*F31*Допущения!$D$24,0)+IF(10-4=Допущения!$D$31,(1-Допущения!$B$36)*G31*Допущения!$D$24,0)+IF(10-5=Допущения!$D$31,(1-Допущения!$B$36)*H31*Допущения!$D$24,0)+IF(10-6=Допущения!$D$31,(1-Допущения!$B$36)*I31*Допущения!$D$24,0)+IF(10-7=Допущения!$D$31,(1-Допущения!$B$36)*J31*Допущения!$D$24,0)+IF(10-8=Допущения!$D$31,(1-Допущения!$B$36)*K31*Допущения!$D$24,0)+IF(10-9=Допущения!$D$31,(1-Допущения!$B$36)*L31*Допущения!$D$24,0) -> 500000 | N38: =Допущения!$B$36*N31*Допущения!$D$24+IF(11-0=Допущения!$D$31,(1-Допущения!$B$36)*C31*Допущения!$D$24,0)+IF(11-1=Допущения!$D$31,(1-Допущения!$B$36)*D31*Допущения!$D$24,0)+IF(11-2=Допущения!$D$31,(1-Допущения!$B$36)*E31*Допущения!$D$24,0)+IF(11-3=Допущения!$D$31,(1-Допущения!$B$36)*F31*Допущения!$D$24,0)+IF(11-4=Допущения!$D$31,(1-Допущения!$B$36)*G31*Допущения!$D$24,0)+IF(11-5=Допущения!$D$31,(1-Допущения!$B$36)*H31*Допущения!$D$24,0)+IF(11-6=Допущения!$D$31,(1-Допущения!$B$36)*I31*Допущения!$D$24,0)+IF(11-7=Допущения!$D$31,(1-Допущения!$B$36)*J31*Допущения!$D$24,0)+IF(11-8=Допущения!$D$31,(1-Допущения!$B$36)*K31*Допущения!$D$24,0)+IF(11-9=Допущения!$D$31,(1-Допущения!$B$36)*L31*Допущения!$D$24,0)+IF(11-10=Допущения!$D$31,(1-Допущения!$B$36)*M31*Допущения!$D$24,0) -> 350000 | O38: =Допущения!$B$36*O31*Допущения!$D$24+IF(12-0=Допущения!$D$31,(1-Допущения!$B$36)*C31*Допущения!$D$24,0)+IF(12-1=Допущения!$D$31,(1-Допущения!$B$36)*D31*Допущения!$D$24,0)+IF(12-2=Допущения!$D$31,(1-Допущения!$B$36)*E31*Допущения!$D$24,0)+IF(12-3=Допущения!$D$31,(1-Допущения!$B$36)*F31*Допущения!$D$24,0)+IF(12-4=Допущения!$D$31,(1-Допущения!$B$36)*G31*Допущения!$D$24,0)+IF(12-5=Допущения!$D$31,(1-Допущения!$B$36)*H31*Допущения!$D$24,0)+IF(12-6=Допущения!$D$31,(1-Допущения!$B$36)*I31*Допущения!$D$24,0)+IF(12-7=Допущения!$D$31,(1-Допущения!$B$36)*J31*Допущения!$D$24,0)+IF(12-8=Допущения!$D$31,(1-Допущения!$B$36)*K31*Допущения!$D$24,0)+IF(12-9=Допущения!$D$31,(1-Допущения!$B$36)*L31*Допущения!$D$24,0)+IF(12-10=Допущения!$D$31,(1-Допущения!$B$36)*M31*Допущения!$D$24,0)+IF(12-11=Допущения!$D$31,(1-Допущения!$B$36)*N31*Допущения!$D$24,0) -> 0 | P38: =SUM(C38:O38) -> 5350000
A39: Комиссия Kaspi + доставка + возвраты | B39: ₸ | C39: =C37*(Допущения!$D$27+Допущения!$D$30)+C35*Допущения!$D$29 -> 0 | D39: =D37*(Допущения!$D$27+Допущения!$D$30)+D35*Допущения!$D$29 -> 0 | E39: =E37*(Допущения!$D$27+Допущения!$D$30)+E35*Допущения!$D$29 -> 402636.52 | F39: =F37*(Допущения!$D$27+Допущения!$D$30)+F35*Допущения!$D$29 -> 263262.34 | G39: =G37*(Допущения!$D$27+Допущения!$D$30)+G35*Допущения!$D$29 -> 263262.34 | H39: =H37*(Допущения!$D$27+Допущения!$D$30)+H35*Допущения!$D$29 -> 309720.4 | I39: =I37*(Допущения!$D$27+Допущения!$D$30)+I35*Допущения!$D$29 -> 278748.36 | J39: =J37*(Допущения!$D$27+Допущения!$D$30)+J35*Допущения!$D$29 -> 294234.38 | ... O39: =O37*(Допущения!$D$27+Допущения!$D$30)+O35*Допущения!$D$29 -> 309720.4 | P39: =SUM(C39:O39) -> 3298522.3
A40: Валовая прибыль (выручка − себест. проданного − Kaspi) | B40: ₸ | C40: =C37-C35*Допущения!$D$24-C39 -> 0 | D40: =D37-D35*Допущения!$D$24-D39 -> 0 | E40: =E37-E35*Допущения!$D$24-E39 -> 842503.48 | F40: =F37-F35*Допущения!$D$24-F39 -> 550867.66 | G40: =G37-G35*Допущения!$D$24-G39 -> 550867.66 | H40: =H37-H35*Допущения!$D$24-H39 -> 648079.6 | I40: =I37-I35*Допущения!$D$24-I39 -> 583271.64 | J40: =J37-J35*Допущения!$D$24-J39 -> 615675.62 | ... O40: =O37-O35*Допущения!$D$24-O39 -> 648079.6 | P40: =SUM(C40:O40) -> 6902047.7
A41: Итого по проекту
...

Sheet Юнит-экономика
A1: ATARIA — юнит-экономика одной продажи на Kaspi
A2: Все цифры тянутся с листа «Допущения»
A4: Статья | B4: Кухонный комбайн AT-SM23 | C4: Подушка 35×60 | D4: Подушка 40×60
A5: Цена продажи, ₸ | B5: =Допущения!$B$25 -> 111514 | C5: =Допущения!$C$25 -> 11344 | D5: =Допущения!$D$25 -> 14578
A6: Себестоимость с доставкой, ₸ | B6: =Допущения!$B$24 -> 50000 | C6: =Допущения!$C$24 -> 4000 | D6: =Допущения!$D$24 -> 5000
A7: Комиссия Kaspi, ₸ | B7: =Допущения!$B$25*Допущения!$B$27 -> 12155.026 | C7: =Допущения!$C$25*Допущения!$C$27 -> 1281.872 | D7: =Допущения!$D$25*Допущения!$D$27 -> 1647.314
A8: Доставка Kaspi за счёт продавца, ₸ | B8: =Допущения!$B$29 -> 1931 | C8: =Допущения!$C$29 -> 998 | D8: =Допущения!$D$29 -> 1377
A9: Возвраты (резерв), ₸ | B9: =Допущения!$B$25*Допущения!$B$30 -> 2787.85 | C9: =Допущения!$C$25*Допущения!$C$30 -> 56.72 | D9: =Допущения!$D$25*Допущения!$D$30 -> 72.89
A10: Налог, ₸ | B10: =Допущения!$B$25*Допущения!$B$37 -> 4460.56 | C10: =Допущения!$C$25*Допущения!$B$37 -> 453.76 | D10: =Допущения!$D$25*Допущения!$B$37 -> 583.12
A11: Маркетинг, ₸ | B11: =Допущения!$B$25*Допущения!$B$28 -> 24766.039 | C11: =Допущения!$C$25*Допущения!$C$28 -> 2337.8199 | D11: =Допущения!$D$25*Допущения!$D$28 -> 3004.2964
A12: Валовая маржа (цена − себестоимость), ₸ | B12: =B5-B6 -> 61514 | C12: =C5-C6 -> 7344 | D12: =D5-D6 -> 9578
A13: Наценка на себестоимость, % | B13: =IF(B6>0,(B5-B6)/B6,0) -> 1.23028 | C13: =IF(C6>0,(C5-C6)/C6,0) -> 1.836 | D13: =IF(D6>0,(D5-D6)/D6,0) -> 1.9156
A14: Валовая маржа, % от цены | B14: =IF(B5>0,(B5-B6)/B5,0) -> 0.5516258 | C14: =IF(C5>0,(C5-C6)/C5,0) -> 0.64739069 | D14: =IF(D5>0,(D5-D6)/D5,0) -> 0.65701742
A15: Прибыль с единицы после всех переменных расходов, ₸ | B15: =B5-SUM(B6:B11) -> 15413.525 | C15: =C5-SUM(C6:C11) -> 2215.8281 | D15: =D5-SUM(D6:D11) -> 2893.3796
A16: Рентабельность продаж (чистая), % | B16: =IF(B5>0,B15/B5,0) -> 0.13822054 | C16: =IF(C5>0,C15/C5,0) -> 0.19533041 | D16: =IF(D5>0,D15/D5,0) -> 0.19847576
A17: Доход на 1 ₸ вложенный в товар (за один оборот), ₸ | B17: =IF(B6>0,B15/B6,0) -> 0.30827051 | C17: =IF(C6>0,C15/C6,0) -> 0.55395704 | D17: =IF(D6>0,D15/D6,0) -> 0.57867593
A20: Цикл оборота денег: комбайн ≈ 3–4 мес. (производство 45–60 дн. + доставка 20–25 дн. + продажа), подушки ≈ 2–2,5 мес. За 12 мес. деньги в подушках оборачиваются ~4–5 раз, в комбайнах ~3 раза.

Sheet Анализ продаж Kaspi
A1: Анализ продаж Kaspi, 24.02.2026 – 14.10.2026
A2: Источник: выгрузки «Архив заказов» Kaspi (ArchiveOrders_13–16), 4 532 строки, дубли между файлами удалены
A4: 1. Общие итоги
A5: Показатель | B5: Сумма, ₸ | C5: Заказов
A6: Выдано заказов всего по Kaspi (как в кабинете), ₸ | B6: 56019787 | C6: 4260
A7: из них технические заказы по 249–1 000 ₸ (самовыкупы), ₸ | B7: 1013257 | C7: 2025
A8: Реальная выручка (без тех. заказов), ₸ | B8: 55006530 | C8: 2235
A9: в т.ч. бренд Ataria (комбайн, измельчители, подушки, аэрогриль), ₸ | B9: 46561590 | C9: 1996
A10: в т.ч. товары брата (не входят в проект), ₸ | B10: 8444940 | C10: 239
A12: 2. Реальные продажи Ataria по месяцам (выданные заказы, без тех. заказов)
A13: Количество, шт.
A14: Товар | B14: 2026-03 | C14: 2026-04 | D14: 2026-05 | E14: 2026-06 | F14: 2026-07 | G14: 2026-08 | H14: 2026-09 | I14: 2026-10 | J14: Итого
A15: Кухонный комбайн AT-SM23 | B15: 0 | C15: 0 | D15: 0 | E15: 0 | F15: 14 | G15: 85 | H15: 55 | I15: 16 | J15: =SUM(B15:I15) -> 170
A16: Измельчитель AT-2300 | B16: 1 | C16: 22 | D16: 65 | E16: 107 | F16: 126 | G16: 103 | H16: 27 | I16: 3 | J16: =SUM(B16:I16) -> 454
A17: Измельчители AT-1100 / AT-1700 | B17: 1 | C17: 5 | D17: 15 | E17: 18 | F17: 9 | G17: 25 | H17: 43 | I17: 17 | J17: =SUM(B17:I17) -> 133
A18: Подушка 35×60 | B18: 0 | C18: 0 | D18: 86 | E18: 152 | F18: 147 | G18: 79 | H18: 98 | I18: 0 | J18: =SUM(B18:I18) -> 562
A19: Подушка 40×60 / 40×61 | B19: 6 | C19: 199 | D19: 97 | E19: 153 | F19: 68 | G19: 50 | H19: 94 | I19: 27 | J19: =SUM(B19:I19) -> 694
A20: Подушка 36×60 (по 29 990–44 990) | B20: 0 | C20: 0 | D20: 8 | E20: 20 | F20: 6 | G20: 1 | H20: 2 | I20: 0 | J20: =SUM(B20:I20) -> 37
A21: Подушка 41×61 (по 27 990–29 990) | B21: 0 | C21: 0 | D21: 1 | E21: 5 | F21: 3 | G21: 4 | H21: 0 | I21: 0 | J21: =SUM(B21:I21) -> 13
A22: Аэрогриль Ataria | B22: 0 | C22: 0 | D22: 21 | E22: 24 | F22: 1 | G22: 0 | H22: 2 | I22: 0 | J22: =SUM(B22:I22) -> 48
A23: Итого | B23: =SUM(B15:B22) -> 8 | C23: =SUM(C15:C22) -> 226 | D23: =SUM(D15:D22) -> 293 | E23: =SUM(E15:E22) -> 479 | F23: =SUM(F15:F22) -> 374 | G23: =SUM(G15:G22) -> 347 | H23: =SUM(H15:H22) -> 321 | I23: =SUM(I15:I22) -> 63 | J23: =SUM(J15:J22) -> 2111
A25: Выручка, ₸
A26: Товар | B26: 2026-03 | C26: 2026-04 | D26: 2026-05 | E26: 2026-06 | F26: 2026-07 | G26: 2026-08 | H26: 2026-09 | I26: 2026-10 | J26: Итого
A27: Кухонный комбайн AT-SM23 | B27: 0 | C27: 0 | D27: 0 | E27: 0 | F27: 1449410 | G27: 9349150 | H27: 6159450 | I27: 1999300 | J27: =SUM(B27:I27) -> 18957310
A28: Измельчитель AT-2300 | B28: 14990 | C28: 329780 | D28: 1013350 | E28: 1644570 | F28: 1824740 | G28: 1544970 | H28: 461730 | I28: 53970 | J28: =SUM(B28:I28) -> 6888100
A29: Измельчители AT-1100 / AT-1700 | B29: 9990 | C29: 49950 | D29: 149850 | E29: 179820 | F29: 89910 | G29: 249750 | H29: 429570 | I29: 169830 | J29: =SUM(B29:I29) -> 1328670
A30: Подушка 35×60 | B30: 0 | C30: 0 | D30: 859140 | E30: 1542480 | F30: 1468530 | G30: 1036210 | H30: 1469020 | I30: 0 | J30: =SUM(B30:I30) -> 6375380
A31: Подушка 40×60 / 40×61 | B31: 89940 | C31: 2983010 | D31: 1468030 | E31: 2044270 | F31: 941820 | G31: 749500 | H31: 1421060 | I31: 419730 | J31: =SUM(B31:I31) -> 10117360
A32: Подушка 36×60 (по 29 990–44 990) | B32: 0 | C32: 0 | D32: 239920 | E32: 603090 | F32: 179400 | G32: 44990 | H32: 89980 | I32: 0 | J32: =SUM(B32:I32) -> 1157380
A33: Подушка 41×61 (по 27 990–29 990) | B33: 0 | C33: 0 | D33: 29990 | E33: 149950 | F33: 85970 | G33: 111960 | H33: 0 | I33: 0 | J33: =SUM(B33:I33) -> 377870
A34: Аэрогриль Ataria | B34: 0 | C34: 0 | D34: 587790 | E34: 687760 | F34: 27990 | G34: 0 | H34: 55980 | I34: 0 | J34: =SUM(B34:I34) -> 1359520
A35: Итого | B35: =SUM(B27:B34) -> 114920 | C35: =SUM(C27:C34) -> 3362740 | D35: =SUM(D27:D34) -> 4348070 | E35: =SUM(E27:E34) -> 6851940 | F35: =SUM(F27:F34) -> 6067770 | G35: =SUM(G27:G34) -> 13086530 | H35: =SUM(H27:H34) -> 10086790 | I35: =SUM(I27:I34) -> 2642830 | J35: =SUM(J27:J34) -> 46561590
A37: 3. Средняя цена, доставка, отмены и возвраты (реальные заказы)
A38: Товар | B38: Продано, шт. | C38: Средняя цена, ₸ | D38: Доставка продавца, ₸/шт. | E38: Доля отмен | F38: Доля возвратов | G38: Доля продаж в кредит/рассрочку
A39: Кухонный комбайн AT-SM23 | B39: 170 | C39: 111514 | D39: 1931 | E39: 0.125 | F39: 0.025 | G39: 0.75882353
A40: Измельчитель AT-2300 | B40: 454 | C40: 15172 | D40: 1497 | E40: 0.0625 | F40: 0.026209677 | G40: 0.36946903
A41: Измельчители AT-1100 / AT-1700 | B41: 133 | C41: 9990 | D41: 909 | E41: 0.049295775 | F41: 0.014084507 | G41: 0.28571429
A42: Подушка 35×60 | B42: 562 | C42: 11344 | D42: 998 | E42: 0.072222222 | F42: 0.0037037037 | G42: 0.28256513
A43: Подушка 40×60 / 40×61 | B43: 694 | C43: 14578 | D43: 1377 | E43: 0.07703281 | F43: 0.0014265335 | G43: 0.27399381
A44: Подушка 36×60 (по 29 990–44 990) | B44: 37 | C44: 31281 | D44: 1435 | E44: 0.1 | F44: 0 | G44: 0.63888889
...

Sheet График платежей
A1: График платежей инвестору
A2: Займ под 4% в месяц, проценты — ежемесячно, тело — одним платежом в конце срока
A4: Месяц | B4: Период | C4: Остаток долга на начало, ₸ | D4: Проценты, ₸ | E4: Возврат тела, ₸ | F4: Итого платёж, ₸ | G4: Остаток долга на конец, ₸
A5: 1 | B5: ноя 26 | C5: ='План и ДДС'!D51 -> 9000000 | D5: ='План и ДДС'!D52 -> 360000 | E5: ='План и ДДС'!D53 -> 0 | F5: =D5+E5 -> 360000 | G5: =C5-E5 -> 9000000
A6: 2 | B6: дек 26 | C6: ='План и ДДС'!E51 -> 9000000 | D6: ='План и ДДС'!E52 -> 360000 | E6: ='План и ДДС'!E53 -> 0 | F6: =D6+E6 -> 360000 | G6: =C6-E6 -> 9000000
A7: 3 | B7: янв 27 | C7: ='План и ДДС'!F51 -> 9000000 | D7: ='План и ДДС'!F52 -> 360000 | E7: ='План и ДДС'!F53 -> 0 | F7: =D7+E7 -> 360000 | G7: =C7-E7 -> 9000000
A8: 4 | B8: фев 27 | C8: ='План и ДДС'!G51 -> 9000000 | D8: ='План и ДДС'!G52 -> 360000 | E8: ='План и ДДС'!G53 -> 0 | F8: =D8+E8 -> 360000 | G8: =C8-E8 -> 9000000
A9: 5 | B9: мар 27 | C9: ='План и ДДС'!H51 -> 9000000 | D9: ='План и ДДС'!H52 -> 360000 | E9: ='План и ДДС'!H53 -> 0 | F9: =D9+E9 -> 360000 | G9: =C9-E9 -> 9000000
A10: 6 | B10: апр 27 | C10: ='План и ДДС'!I51 -> 9000000 | D10: ='План и ДДС'!I52 -> 360000 | E10: ='План и ДДС'!I53 -> 0 | F10: =D10+E10 -> 360000 | G10: =C10-E10 -> 9000000
A11: 7 | B11: май 27 | C11: ='План и ДДС'!J51 -> 9000000 | D11: ='План и ДДС'!J52 -> 360000 | E11: ='План и ДДС'!J53 -> 0 | F11: =D11+E11 -> 360000 | G11: =C11-E11 -> 9000000
A12: 8 | B12: июн 27 | C12: ='План и ДДС'!K51 -> 9000000 | D12: ='План и ДДС'!K52 -> 360000 | E12: ='План и ДДС'!K53 -> 0 | F12: =D12+E12 -> 360000 | G12: =C12-E12 -> 9000000
A13: 9 | B13: июл 27 | C13: ='План и ДДС'!L51 -> 9000000 | D13: ='План и ДДС'!L52 -> 360000 | E13: ='План и ДДС'!L53 -> 0 | F13: =D13+E13 -> 360000 | G13: =C13-E13 -> 9000000
A14: 10 | B14: авг 27 | C14: ='План и ДДС'!M51 -> 9000000 | D14: ='План и ДДС'!M52 -> 360000 | E14: ='План и ДДС'!M53 -> 0 | F14: =D14+E14 -> 360000 | G14: =C14-E14 -> 9000000
A15: 11 | B15: сен 27 | C15: ='План и ДДС'!N51 -> 9000000 | D15: ='План и ДДС'!N52 -> 360000 | E15: ='План и ДДС'!N53 -> 0 | F15: =D15+E15 -> 360000 | G15: =C15-E15 -> 9000000
A16: 12 | B16: окт 27 | C16: ='План и ДДС'!O51 -> 9000000 | D16: ='План и ДДС'!O52 -> 360000 | E16: ='План и ДДС'!O53 -> 9000000 | F16: =D16+E16 -> 9360000 | G16: =C16-E16 -> 0
A17: Итого | D17: =SUM(D5:D16) -> 4320000 | E17: =SUM(E5:E16) -> 9000000 | F17: =SUM(F5:F16) -> 13320000
A19: Доходность инвестора
A20: Сумма займа, ₸ | C20: =Допущения!$B$6+Допущения!$B$7+Допущения!$B$9+Допущения!$B$10 -> 9000000
A21: Проценты за срок, ₸ | C21: =D17 -> 4320000
A22: Возврат всего, ₸ | C22: =F17 -> 13320000
A23: Доходность за срок, % | C23: =IF(C20>0,C21/C20,0) -> 0.48
A24: Годовая ставка (простая), % | C24: =Допущения!$B$12*12 -> 0.48
A25: Эффективная годовая (с реинвестированием процентов), % | C25: =(1+Допущения!$B$12)^12-1 -> 0.60103222

Sheet Анализ маркетинга
A1: Анализ маркетинга Kaspi, 01.01–15.10.2026
A2: Источник: отчёты Kaspi — реклама (оплата за клик), бонусы покупателям, бонусы за отзывы, доп. рекламный отчёт (xlsx). Кампании «Жигер» = товары брата.
A4: Группа товаров | B4: Реклама Kaspi (клики), ₸ | C4: Бонусы покупателям, ₸ | D4: Бонусы за отзывы, ₸ | E4: Доп. рекламный отчёт, ₸ | F4: Маркетинг всего, ₸ | G4: Реальная выручка, ₸ | H4: Маркетинг, % от выручки
A5: Кухонный комбайн AT-SM23 | B5: 4058090 | C5: 59091 | D5: 50600 | E5: 42430 | F5: =SUM(B5:E5) -> 4210211 | G5: 18957310 | H5: =IF(G5>0,F5/G5,0) -> 0.22208905
A6: Подушки (все размеры) | B6: 3462385 | C6: 169269 | D6: 39700 | E6: 43931 | F6: =SUM(B6:E6) -> 3715285 | G6: 18027990 | H6: =IF(G6>0,F6/G6,0) -> 0.20608426
A7: Измельчители AT-2300 / 1100 / 1700 | B7: 1770967 | C7: 98042 | D7: 30650 | E7: 38964 | F7: =SUM(B7:E7) -> 1938623 | G7: 8216770 | H7: =IF(G7>0,F7/G7,0) -> 0.23593492
A8: Аэрогриль | B8: 328739 | C8: 0 | D8: 1600 | E8: 251 | F8: =SUM(B8:E8) -> 330590 | G8: 1359520 | H8: =IF(G8>0,F8/G8,0) -> 0.24316671
A9: Товары брата («Жигер») | B9: 741047 | C9: 166336 | D9: 83000 | E9: 15020 | F9: =SUM(B9:E9) -> 1005403 | G9: 8444940 | H9: =IF(G9>0,F9/G9,0) -> 0.11905389
A10: Прочие кампании (плазменная ручка и др.) | B10: 0 | C10: 1848 | D10: 0 | E10: 0 | F10: =SUM(B10:E10) -> 1848 | G10: 0 | H10: =IF(G10>0,F10/G10,0) -> 0
A11: Итого | B11: =SUM(B5:B10) -> 10361228 | C11: =SUM(C5:C10) -> 494586 | D11: =SUM(D5:D10) -> 205550 | E11: =SUM(E5:E10) -> 140596 | F11: =SUM(F5:F10) -> 11201960 | G11: =SUM(G5:G10) -> 55006530 | H11: =IF(G11>0,F11/G11,0) -> 0.20364782
A12: Итого бренд Ataria (без брата) | F12: =F5+F6+F7+F8 -> 10194709 | G12: =G5+G6+G7+G8 -> 46561590 | H12: =IF(G12>0,F12/G12,0) -> 0.21895105
A14: Ключевые кампании (реклама Kaspi)
A15: Кампания | B15: Расход, ₸ | C15: Клики | D15: Цена клика, ₸ | E15: Заказы | F15: Сумма заказов, ₸ | G15: ДРР, % | H15: Конверсия клик→заказ
A16: Комбайн AT-SM23 2 | B16: 3789397 | C16: 11665 | D16: 325 | E16: 155 | F16: 17357910 | G16: =IF(F16>0,B16/F16,0) -> 0.21830952 | H16: =IF(C16>0,E16/C16,0) -> 0.013287613
A17: Подушка волна | B17: 1744772 | C17: 12215 | D17: 143 | E17: 460 | F17: 6375790 | G17: =IF(F17>0,B17/F17,0) -> 0.27365581 | H17: =IF(C17>0,E17/C17,0) -> 0.037658616
A18: Подушка | B18: 1588897 | C18: 14169 | D18: 112 | E18: 436 | F18: 6891770 | G18: =IF(F18>0,B18/F18,0) -> 0.23054992 | H18: =IF(C18>0,E18/C18,0) -> 0.030771402
A19: 2300 | B19: 1501744 | C19: 12343 | D19: 122 | E19: 331 | F19: 5007400 | G19: =IF(F19>0,B19/F19,0) -> 0.29990494 | H19: =IF(C19>0,E19/C19,0) -> 0.026816819
A20: Аэрогриль | B20: 328489 | C20: 1491 | D20: 220 | E20: 39 | F20: 1101610 | G20: =IF(F20>0,B20/F20,0) -> 0.29818992 | H20: =IF(C20>0,E20/C20,0) -> 0.026156942
A21: Комбайн AT-SM23 | B21: 268693 | C21: 673 | D21: 399 | E21: 5 | F21: 509590 | G21: =IF(F21>0,B21/F21,0) -> 0.52727291 | H21: =IF(C21>0,E21/C21,0) -> 0.0074294205
A22: At-1100 | B22: 128301 | C22: 1490 | D22: 86 | E22: 47 | F22: 488530 | G22: =IF(F22>0,B22/F22,0) -> 0.26262666 | H22: =IF(C22>0,E22/C22,0) -> 0.031543624
A23: At-170” | B23: 127205 | C23: 1495 | D23: 85 | E23: 52 | F23: 529480 | G23: =IF(F23>0,B23/F23,0) -> 0.24024515 | H23: =IF(C23>0,E23/C23,0) -> 0.034782609
A24: Подушка шелк | B24: 59780 | C24: 880 | D24: 68 | E24: 16 | F24: 258729 | G24: =IF(F24>0,B24/F24,0) -> 0.23105257 | H24: =IF(C24>0,E24/C24,0) -> 0.018181818
A25: 3+1 волна | B25: 59234 | C25: 483 | D25: 123 | E25: 18 | F25: 563810 | G25: =IF(F25>0,B25/F25,0) -> 0.10506022 | H25: =IF(C25>0,E25/C25,0) -> 0.037267081
A27: Выводы:
A28: • Маркетинг бренда Ataria — около 9,9 млн ₸ за 9,5 мес., примерно 21% реальной выручки. Основная статья — реклама Kaspi с оплатой за клик (95% расходов).
A29: • Комбайн: клик стоит 325–400 ₸ (дороже всех), ДРР ≈ 22%. Это главный резерв: снижение ДРР до 15% даёт +8 000 ₸ прибыли с каждого комбайна.
A30: • Подушки: клик дешёвый (110–145 ₸), но конверсия 3–4%, ДРР 23–27%. Есть потенциал в Instagram-магазине и отзывах.
A31: • Бонусы за отзывы работают хорошо: 367 отзывов за 205 тыс. ₸, конверсия 22–36%.
A32: • Технические заказы (самовыкупы) не включены в маркетинг — их затраты незначительны, но в выручку они тоже не входят.

Sheet Факт прибыли 2026
A1: Фактическая прибыль бренда Ataria, март–октябрь 2026
A2: Реальные продажи Kaspi (без самовыкупов и товаров брата) × себестоимость со слов владельца. Маркетинг — факт из отчётов Kaspi.
A4: Товар | B4: Продано, шт. | C4: Средняя цена, ₸ | D4: Выручка, ₸ | E4: Себестоимость ед., ₸ | F4: Себестоимость всего, ₸ | G4: Комиссия Kaspi, ₸ | H4: Доставка, ₸ | I4: Маркетинг, ₸ | J4: Налог 4%, ₸ | K4: Прибыль, ₸ | L4: Маржа, % | M4: Наценка, %
A5: Кухонный комбайн AT-SM23 | B5: 170 | C5: =IF(B5>0,D5/B5,0) -> 111513.59 | D5: 18957310 | E5: 50000 | F5: =B5*E5 -> 8500000 | G5: =D5*0.109 -> 2066346.8 | H5: 328342 | I5: ='Анализ маркетинга'!F5*D5/18957310 -> 4210211 | J5: =D5*Допущения!$B$37 -> 758292.4 | K5: =D5-F5-G5-H5-I5-J5 -> 3094117.8 | L5: =IF(D5>0,K5/D5,0) -> 0.16321502 | M5: =IF(E5>0,(C5-E5)/E5,0) -> 1.2302718
A6: Подушка 35×60 | B6: 562 | C6: =IF(B6>0,D6/B6,0) -> 11344.093 | D6: 6375380 | E6: 4000 | F6: =B6*E6 -> 2248000 | G6: =D6*0.113 -> 720417.94 | H6: 560941 | I6: ='Анализ маркетинга'!F6*D6/18027990 -> 1313865.5 | J6: =D6*Допущения!$B$37 -> 255015.2 | K6: =D6-F6-G6-H6-I6-J6 -> 1277140.4 | L6: =IF(D6>0,K6/D6,0) -> 0.20032381 | M6: =IF(E6>0,(C6-E6)/E6,0) -> 1.8360231
A7: Подушка 40×60 | B7: 629 | C7: =IF(B7>0,D7/B7,0) -> 14522.591 | D7: 9134710 | E7: 5000 | F7: =B7*E7 -> 3145000 | G7: =D7*0.113 -> 1032222.2 | H7: 867905 | I7: ='Анализ маркетинга'!F6*D7/18027990 -> 1882520 | J7: =D7*Допущения!$B$37 -> 365388.4 | K7: =D7-F7-G7-H7-I7-J7 -> 1841674.4 | L7: =IF(D7>0,K7/D7,0) -> 0.20161279 | M7: =IF(E7>0,(C7-E7)/E7,0) -> 1.9045183
